2024-02-01 15:42:44,680 (INFO) - flower.command - Visit me at http://0.0.0.0:5555
2024-02-01 15:42:44,795 (INFO) - flower.command - Broker: redis://localhost:6376/1
2024-02-01 15:42:44,812 (INFO) - flower.command - Registered tasks: 
['celery.accumulate',
 'celery.backend_cleanup',
 'celery.chain',
 'celery.chord',
 'celery.chord_unlock',
 'celery.chunks',
 'celery.group',
 'celery.map',
 'celery.starmap',
 'playground.tasks.notify_customers']
2024-02-01 15:42:51,750 (ERROR) - asyncio - Future exception was never retrieved
future: <Future finished exception=OperationalError('Connection closed by server.')>
Traceback (most recent call last):
  File "C:\Users\DELL\Desktop\portofolio_project\venv\Lib\site-packages\kombu\transport\virtual\base.py", line 951, in create_channel
    return self._avail_channels.pop()
           ^^^^^^^^^^^^^^^^^^^^^^^^^^
IndexError: pop from empty list

During handling of the above exception, another exception occurred:

Traceback (most recent call last):
  File "C:\Users\DELL\Desktop\portofolio_project\venv\Lib\site-packages\kombu\connection.py", line 472, in _reraise_as_library_errors
    yield
  File "C:\Users\DELL\Desktop\portofolio_project\venv\Lib\site-packages\kombu\connection.py", line 459, in _ensure_connection
    return retry_over_time(
           ^^^^^^^^^^^^^^^^
  File "C:\Users\DELL\Desktop\portofolio_project\venv\Lib\site-packages\kombu\utils\functional.py", line 318, in retry_over_time
    return fun(*args, **kwargs)
           ^^^^^^^^^^^^^^^^^^^^
  File "C:\Users\DELL\Desktop\portofolio_project\venv\Lib\site-packages\kombu\connection.py", line 934, in _connection_factory
    self._connection = self._establish_connection()
                       ^^^^^^^^^^^^^^^^^^^^^^^^^^^^
  File "C:\Users\DELL\Desktop\portofolio_project\venv\Lib\site-packages\kombu\connection.py", line 860, in _establish_connection
    conn = self.transport.establish_connection()
           ^^^^^^^^^^^^^^^^^^^^^^^^^^^^^^^^^^^^^
  File "C:\Users\DELL\Desktop\portofolio_project\venv\Lib\site-packages\kombu\transport\virtual\base.py", line 975, in establish_connection
    self._avail_channels.append(self.create_channel(self))
                                ^^^^^^^^^^^^^^^^^^^^^^^^^
  File "C:\Users\DELL\Desktop\portofolio_project\venv\Lib\site-packages\kombu\transport\virtual\base.py", line 953, in create_channel
    channel = self.Channel(connection)
              ^^^^^^^^^^^^^^^^^^^^^^^^
  File "C:\Users\DELL\Desktop\portofolio_project\venv\Lib\site-packages\kombu\transport\redis.py", line 743, in __init__
    self.client.ping()
  File "C:\Users\DELL\Desktop\portofolio_project\venv\Lib\site-packages\redis\commands\core.py", line 1216, in ping
    return self.execute_command("PING", **kwargs)
           ^^^^^^^^^^^^^^^^^^^^^^^^^^^^^^^^^^^^^^
  File "C:\Users\DELL\Desktop\portofolio_project\venv\Lib\site-packages\redis\client.py", line 533, in execute_command
    conn = self.connection or pool.get_connection(command_name, **options)
                              ^^^^^^^^^^^^^^^^^^^^^^^^^^^^^^^^^^^^^^^^^^^^
  File "C:\Users\DELL\Desktop\portofolio_project\venv\Lib\site-packages\redis\connection.py", line 1086, in get_connection
    connection.connect()
  File "C:\Users\DELL\Desktop\portofolio_project\venv\Lib\site-packages\redis\connection.py", line 276, in connect
    self.on_connect()
  File "C:\Users\DELL\Desktop\portofolio_project\venv\Lib\site-packages\redis\connection.py", line 378, in on_connect
    self.send_command("CLIENT", "SETINFO", "LIB-NAME", self.lib_name)
  File "C:\Users\DELL\Desktop\portofolio_project\venv\Lib\site-packages\redis\connection.py", line 464, in send_command
    self.send_packed_command(
  File "C:\Users\DELL\Desktop\portofolio_project\venv\Lib\site-packages\redis\connection.py", line 437, in send_packed_command
    self.check_health()
  File "C:\Users\DELL\Desktop\portofolio_project\venv\Lib\site-packages\redis\connection.py", line 429, in check_health
    self.retry.call_with_retry(self._send_ping, self._ping_failed)
  File "C:\Users\DELL\Desktop\portofolio_project\venv\Lib\site-packages\redis\retry.py", line 51, in call_with_retry
    raise error
  File "C:\Users\DELL\Desktop\portofolio_project\venv\Lib\site-packages\redis\retry.py", line 46, in call_with_retry
    return do()
           ^^^^
  File "C:\Users\DELL\Desktop\portofolio_project\venv\Lib\site-packages\redis\connection.py", line 419, in _send_ping
    if str_if_bytes(self.read_response()) != "PONG":
                    ^^^^^^^^^^^^^^^^^^^^
  File "C:\Users\DELL\Desktop\portofolio_project\venv\Lib\site-packages\redis\connection.py", line 500, in read_response
    response = self._parser.read_response(disable_decoding=disable_decoding)
               ^^^^^^^^^^^^^^^^^^^^^^^^^^^^^^^^^^^^^^^^^^^^^^^^^^^^^^^^^^^^^
  File "C:\Users\DELL\Desktop\portofolio_project\venv\Lib\site-packages\redis\_parsers\resp2.py", line 15, in read_response
    result = self._read_response(disable_decoding=disable_decoding)
             ^^^^^^^^^^^^^^^^^^^^^^^^^^^^^^^^^^^^^^^^^^^^^^^^^^^^^^
  File "C:\Users\DELL\Desktop\portofolio_project\venv\Lib\site-packages\redis\_parsers\resp2.py", line 25, in _read_response
    raw = self._buffer.readline()
          ^^^^^^^^^^^^^^^^^^^^^^^
  File "C:\Users\DELL\Desktop\portofolio_project\venv\Lib\site-packages\redis\_parsers\socket.py", line 115, in readline
    self._read_from_socket()
  File "C:\Users\DELL\Desktop\portofolio_project\venv\Lib\site-packages\redis\_parsers\socket.py", line 68, in _read_from_socket
    raise ConnectionError(SERVER_CLOSED_CONNECTION_ERROR)
redis.exceptions.ConnectionError: Connection closed by server.

The above exception was the direct cause of the following exception:

Traceback (most recent call last):
  File "C:\Users\DELL\AppData\Local\Programs\Python\Python312\Lib\concurrent\futures\thread.py", line 58, in run
    result = self.fn(*self.args, **self.kwargs)
             ^^^^^^^^^^^^^^^^^^^^^^^^^^^^^^^^^^
  File "C:\Users\DELL\Desktop\portofolio_project\venv\Lib\site-packages\flower\inspector.py", line 39, in _inspect
    else getattr(inspect, method)(safe=True)
         ^^^^^^^^^^^^^^^^^^^^^^^^^^^^^^^^^^^
  File "C:\Users\DELL\Desktop\portofolio_project\venv\Lib\site-packages\celery\app\control.py", line 149, in active
    return self._request('active', safe=safe)
           ^^^^^^^^^^^^^^^^^^^^^^^^^^^^^^^^^^
  File "C:\Users\DELL\Desktop\portofolio_project\venv\Lib\site-packages\celery\app\control.py", line 106, in _request
    return self._prepare(self.app.control.broadcast(
                         ^^^^^^^^^^^^^^^^^^^^^^^^^^^
  File "C:\Users\DELL\Desktop\portofolio_project\venv\Lib\site-packages\celery\app\control.py", line 776, in broadcast
    return self.mailbox(conn)._broadcast(
           ^^^^^^^^^^^^^^^^^^^^^^^^^^^^^^
  File "C:\Users\DELL\Desktop\portofolio_project\venv\Lib\site-packages\kombu\pidbox.py", line 330, in _broadcast
    chan = channel or self.connection.default_channel
                      ^^^^^^^^^^^^^^^^^^^^^^^^^^^^^^^
  File "C:\Users\DELL\Desktop\portofolio_project\venv\Lib\site-packages\kombu\connection.py", line 953, in default_channel
    self._ensure_connection(**conn_opts)
  File "C:\Users\DELL\Desktop\portofolio_project\venv\Lib\site-packages\kombu\connection.py", line 458, in _ensure_connection
    with ctx():
  File "C:\Users\DELL\AppData\Local\Programs\Python\Python312\Lib\contextlib.py", line 158, in __exit__
    self.gen.throw(value)
  File "C:\Users\DELL\Desktop\portofolio_project\venv\Lib\site-packages\kombu\connection.py", line 476, in _reraise_as_library_errors
    raise ConnectionError(str(exc)) from exc
kombu.exceptions.OperationalError: Connection closed by server.
2024-02-01 15:42:51,781 (ERROR) - flower.events - Failed to capture events: 'Connection closed by server.', trying again in 2 seconds.
2024-02-01 15:42:51,806 (ERROR) - asyncio - Future exception was never retrieved
future: <Future finished exception=OperationalError('Connection closed by server.')>
Traceback (most recent call last):
  File "C:\Users\DELL\Desktop\portofolio_project\venv\Lib\site-packages\kombu\transport\virtual\base.py", line 951, in create_channel
    return self._avail_channels.pop()
           ^^^^^^^^^^^^^^^^^^^^^^^^^^
IndexError: pop from empty list

During handling of the above exception, another exception occurred:

Traceback (most recent call last):
  File "C:\Users\DELL\Desktop\portofolio_project\venv\Lib\site-packages\kombu\connection.py", line 472, in _reraise_as_library_errors
    yield
  File "C:\Users\DELL\Desktop\portofolio_project\venv\Lib\site-packages\kombu\connection.py", line 459, in _ensure_connection
    return retry_over_time(
           ^^^^^^^^^^^^^^^^
  File "C:\Users\DELL\Desktop\portofolio_project\venv\Lib\site-packages\kombu\utils\functional.py", line 318, in retry_over_time
    return fun(*args, **kwargs)
           ^^^^^^^^^^^^^^^^^^^^
  File "C:\Users\DELL\Desktop\portofolio_project\venv\Lib\site-packages\kombu\connection.py", line 934, in _connection_factory
    self._connection = self._establish_connection()
                       ^^^^^^^^^^^^^^^^^^^^^^^^^^^^
  File "C:\Users\DELL\Desktop\portofolio_project\venv\Lib\site-packages\kombu\connection.py", line 860, in _establish_connection
    conn = self.transport.establish_connection()
           ^^^^^^^^^^^^^^^^^^^^^^^^^^^^^^^^^^^^^
  File "C:\Users\DELL\Desktop\portofolio_project\venv\Lib\site-packages\kombu\transport\virtual\base.py", line 975, in establish_connection
    self._avail_channels.append(self.create_channel(self))
                                ^^^^^^^^^^^^^^^^^^^^^^^^^
  File "C:\Users\DELL\Desktop\portofolio_project\venv\Lib\site-packages\kombu\transport\virtual\base.py", line 953, in create_channel
    channel = self.Channel(connection)
              ^^^^^^^^^^^^^^^^^^^^^^^^
  File "C:\Users\DELL\Desktop\portofolio_project\venv\Lib\site-packages\kombu\transport\redis.py", line 743, in __init__
    self.client.ping()
  File "C:\Users\DELL\Desktop\portofolio_project\venv\Lib\site-packages\redis\commands\core.py", line 1216, in ping
    return self.execute_command("PING", **kwargs)
           ^^^^^^^^^^^^^^^^^^^^^^^^^^^^^^^^^^^^^^
  File "C:\Users\DELL\Desktop\portofolio_project\venv\Lib\site-packages\redis\client.py", line 533, in execute_command
    conn = self.connection or pool.get_connection(command_name, **options)
                              ^^^^^^^^^^^^^^^^^^^^^^^^^^^^^^^^^^^^^^^^^^^^
  File "C:\Users\DELL\Desktop\portofolio_project\venv\Lib\site-packages\redis\connection.py", line 1086, in get_connection
    connection.connect()
  File "C:\Users\DELL\Desktop\portofolio_project\venv\Lib\site-packages\redis\connection.py", line 276, in connect
    self.on_connect()
  File "C:\Users\DELL\Desktop\portofolio_project\venv\Lib\site-packages\redis\connection.py", line 378, in on_connect
    self.send_command("CLIENT", "SETINFO", "LIB-NAME", self.lib_name)
  File "C:\Users\DELL\Desktop\portofolio_project\venv\Lib\site-packages\redis\connection.py", line 464, in send_command
    self.send_packed_command(
  File "C:\Users\DELL\Desktop\portofolio_project\venv\Lib\site-packages\redis\connection.py", line 437, in send_packed_command
    self.check_health()
  File "C:\Users\DELL\Desktop\portofolio_project\venv\Lib\site-packages\redis\connection.py", line 429, in check_health
    self.retry.call_with_retry(self._send_ping, self._ping_failed)
  File "C:\Users\DELL\Desktop\portofolio_project\venv\Lib\site-packages\redis\retry.py", line 51, in call_with_retry
    raise error
  File "C:\Users\DELL\Desktop\portofolio_project\venv\Lib\site-packages\redis\retry.py", line 46, in call_with_retry
    return do()
           ^^^^
  File "C:\Users\DELL\Desktop\portofolio_project\venv\Lib\site-packages\redis\connection.py", line 419, in _send_ping
    if str_if_bytes(self.read_response()) != "PONG":
                    ^^^^^^^^^^^^^^^^^^^^
  File "C:\Users\DELL\Desktop\portofolio_project\venv\Lib\site-packages\redis\connection.py", line 500, in read_response
    response = self._parser.read_response(disable_decoding=disable_decoding)
               ^^^^^^^^^^^^^^^^^^^^^^^^^^^^^^^^^^^^^^^^^^^^^^^^^^^^^^^^^^^^^
  File "C:\Users\DELL\Desktop\portofolio_project\venv\Lib\site-packages\redis\_parsers\resp2.py", line 15, in read_response
    result = self._read_response(disable_decoding=disable_decoding)
             ^^^^^^^^^^^^^^^^^^^^^^^^^^^^^^^^^^^^^^^^^^^^^^^^^^^^^^
  File "C:\Users\DELL\Desktop\portofolio_project\venv\Lib\site-packages\redis\_parsers\resp2.py", line 25, in _read_response
    raw = self._buffer.readline()
          ^^^^^^^^^^^^^^^^^^^^^^^
  File "C:\Users\DELL\Desktop\portofolio_project\venv\Lib\site-packages\redis\_parsers\socket.py", line 115, in readline
    self._read_from_socket()
  File "C:\Users\DELL\Desktop\portofolio_project\venv\Lib\site-packages\redis\_parsers\socket.py", line 68, in _read_from_socket
    raise ConnectionError(SERVER_CLOSED_CONNECTION_ERROR)
redis.exceptions.ConnectionError: Connection closed by server.

The above exception was the direct cause of the following exception:

Traceback (most recent call last):
  File "C:\Users\DELL\AppData\Local\Programs\Python\Python312\Lib\concurrent\futures\thread.py", line 58, in run
    result = self.fn(*self.args, **self.kwargs)
             ^^^^^^^^^^^^^^^^^^^^^^^^^^^^^^^^^^
  File "C:\Users\DELL\Desktop\portofolio_project\venv\Lib\site-packages\flower\inspector.py", line 37, in _inspect
    getattr(inspect, method)()
  File "C:\Users\DELL\Desktop\portofolio_project\venv\Lib\site-packages\celery\app\control.py", line 386, in conf
    return self._request('conf', with_defaults=with_defaults)
           ^^^^^^^^^^^^^^^^^^^^^^^^^^^^^^^^^^^^^^^^^^^^^^^^^^
  File "C:\Users\DELL\Desktop\portofolio_project\venv\Lib\site-packages\celery\app\control.py", line 106, in _request
    return self._prepare(self.app.control.broadcast(
                         ^^^^^^^^^^^^^^^^^^^^^^^^^^^
  File "C:\Users\DELL\Desktop\portofolio_project\venv\Lib\site-packages\celery\app\control.py", line 776, in broadcast
    return self.mailbox(conn)._broadcast(
           ^^^^^^^^^^^^^^^^^^^^^^^^^^^^^^
  File "C:\Users\DELL\Desktop\portofolio_project\venv\Lib\site-packages\kombu\pidbox.py", line 330, in _broadcast
    chan = channel or self.connection.default_channel
                      ^^^^^^^^^^^^^^^^^^^^^^^^^^^^^^^
  File "C:\Users\DELL\Desktop\portofolio_project\venv\Lib\site-packages\kombu\connection.py", line 953, in default_channel
    self._ensure_connection(**conn_opts)
  File "C:\Users\DELL\Desktop\portofolio_project\venv\Lib\site-packages\kombu\connection.py", line 458, in _ensure_connection
    with ctx():
  File "C:\Users\DELL\AppData\Local\Programs\Python\Python312\Lib\contextlib.py", line 158, in __exit__
    self.gen.throw(value)
  File "C:\Users\DELL\Desktop\portofolio_project\venv\Lib\site-packages\kombu\connection.py", line 476, in _reraise_as_library_errors
    raise ConnectionError(str(exc)) from exc
kombu.exceptions.OperationalError: Connection closed by server.
2024-02-01 15:42:51,821 (ERROR) - asyncio - Future exception was never retrieved
future: <Future finished exception=OperationalError('Connection closed by server.')>
Traceback (most recent call last):
  File "C:\Users\DELL\Desktop\portofolio_project\venv\Lib\site-packages\kombu\transport\virtual\base.py", line 951, in create_channel
    return self._avail_channels.pop()
           ^^^^^^^^^^^^^^^^^^^^^^^^^^
IndexError: pop from empty list

During handling of the above exception, another exception occurred:

Traceback (most recent call last):
  File "C:\Users\DELL\Desktop\portofolio_project\venv\Lib\site-packages\kombu\connection.py", line 472, in _reraise_as_library_errors
    yield
  File "C:\Users\DELL\Desktop\portofolio_project\venv\Lib\site-packages\kombu\connection.py", line 459, in _ensure_connection
    return retry_over_time(
           ^^^^^^^^^^^^^^^^
  File "C:\Users\DELL\Desktop\portofolio_project\venv\Lib\site-packages\kombu\utils\functional.py", line 318, in retry_over_time
    return fun(*args, **kwargs)
           ^^^^^^^^^^^^^^^^^^^^
  File "C:\Users\DELL\Desktop\portofolio_project\venv\Lib\site-packages\kombu\connection.py", line 934, in _connection_factory
    self._connection = self._establish_connection()
                       ^^^^^^^^^^^^^^^^^^^^^^^^^^^^
  File "C:\Users\DELL\Desktop\portofolio_project\venv\Lib\site-packages\kombu\connection.py", line 860, in _establish_connection
    conn = self.transport.establish_connection()
           ^^^^^^^^^^^^^^^^^^^^^^^^^^^^^^^^^^^^^
  File "C:\Users\DELL\Desktop\portofolio_project\venv\Lib\site-packages\kombu\transport\virtual\base.py", line 975, in establish_connection
    self._avail_channels.append(self.create_channel(self))
                                ^^^^^^^^^^^^^^^^^^^^^^^^^
  File "C:\Users\DELL\Desktop\portofolio_project\venv\Lib\site-packages\kombu\transport\virtual\base.py", line 953, in create_channel
    channel = self.Channel(connection)
              ^^^^^^^^^^^^^^^^^^^^^^^^
  File "C:\Users\DELL\Desktop\portofolio_project\venv\Lib\site-packages\kombu\transport\redis.py", line 743, in __init__
    self.client.ping()
  File "C:\Users\DELL\Desktop\portofolio_project\venv\Lib\site-packages\redis\commands\core.py", line 1216, in ping
    return self.execute_command("PING", **kwargs)
           ^^^^^^^^^^^^^^^^^^^^^^^^^^^^^^^^^^^^^^
  File "C:\Users\DELL\Desktop\portofolio_project\venv\Lib\site-packages\redis\client.py", line 533, in execute_command
    conn = self.connection or pool.get_connection(command_name, **options)
                              ^^^^^^^^^^^^^^^^^^^^^^^^^^^^^^^^^^^^^^^^^^^^
  File "C:\Users\DELL\Desktop\portofolio_project\venv\Lib\site-packages\redis\connection.py", line 1086, in get_connection
    connection.connect()
  File "C:\Users\DELL\Desktop\portofolio_project\venv\Lib\site-packages\redis\connection.py", line 276, in connect
    self.on_connect()
  File "C:\Users\DELL\Desktop\portofolio_project\venv\Lib\site-packages\redis\connection.py", line 378, in on_connect
    self.send_command("CLIENT", "SETINFO", "LIB-NAME", self.lib_name)
  File "C:\Users\DELL\Desktop\portofolio_project\venv\Lib\site-packages\redis\connection.py", line 464, in send_command
    self.send_packed_command(
  File "C:\Users\DELL\Desktop\portofolio_project\venv\Lib\site-packages\redis\connection.py", line 437, in send_packed_command
    self.check_health()
  File "C:\Users\DELL\Desktop\portofolio_project\venv\Lib\site-packages\redis\connection.py", line 429, in check_health
    self.retry.call_with_retry(self._send_ping, self._ping_failed)
  File "C:\Users\DELL\Desktop\portofolio_project\venv\Lib\site-packages\redis\retry.py", line 51, in call_with_retry
    raise error
  File "C:\Users\DELL\Desktop\portofolio_project\venv\Lib\site-packages\redis\retry.py", line 46, in call_with_retry
    return do()
           ^^^^
  File "C:\Users\DELL\Desktop\portofolio_project\venv\Lib\site-packages\redis\connection.py", line 419, in _send_ping
    if str_if_bytes(self.read_response()) != "PONG":
                    ^^^^^^^^^^^^^^^^^^^^
  File "C:\Users\DELL\Desktop\portofolio_project\venv\Lib\site-packages\redis\connection.py", line 500, in read_response
    response = self._parser.read_response(disable_decoding=disable_decoding)
               ^^^^^^^^^^^^^^^^^^^^^^^^^^^^^^^^^^^^^^^^^^^^^^^^^^^^^^^^^^^^^
  File "C:\Users\DELL\Desktop\portofolio_project\venv\Lib\site-packages\redis\_parsers\resp2.py", line 15, in read_response
    result = self._read_response(disable_decoding=disable_decoding)
             ^^^^^^^^^^^^^^^^^^^^^^^^^^^^^^^^^^^^^^^^^^^^^^^^^^^^^^
  File "C:\Users\DELL\Desktop\portofolio_project\venv\Lib\site-packages\redis\_parsers\resp2.py", line 25, in _read_response
    raw = self._buffer.readline()
          ^^^^^^^^^^^^^^^^^^^^^^^
  File "C:\Users\DELL\Desktop\portofolio_project\venv\Lib\site-packages\redis\_parsers\socket.py", line 115, in readline
    self._read_from_socket()
  File "C:\Users\DELL\Desktop\portofolio_project\venv\Lib\site-packages\redis\_parsers\socket.py", line 68, in _read_from_socket
    raise ConnectionError(SERVER_CLOSED_CONNECTION_ERROR)
redis.exceptions.ConnectionError: Connection closed by server.

The above exception was the direct cause of the following exception:

Traceback (most recent call last):
  File "C:\Users\DELL\AppData\Local\Programs\Python\Python312\Lib\concurrent\futures\thread.py", line 58, in run
    result = self.fn(*self.args, **self.kwargs)
             ^^^^^^^^^^^^^^^^^^^^^^^^^^^^^^^^^^
  File "C:\Users\DELL\Desktop\portofolio_project\venv\Lib\site-packages\flower\inspector.py", line 37, in _inspect
    getattr(inspect, method)()
  File "C:\Users\DELL\Desktop\portofolio_project\venv\Lib\site-packages\celery\app\control.py", line 338, in active_queues
    return self._request('active_queues')
           ^^^^^^^^^^^^^^^^^^^^^^^^^^^^^^
  File "C:\Users\DELL\Desktop\portofolio_project\venv\Lib\site-packages\celery\app\control.py", line 106, in _request
    return self._prepare(self.app.control.broadcast(
                         ^^^^^^^^^^^^^^^^^^^^^^^^^^^
  File "C:\Users\DELL\Desktop\portofolio_project\venv\Lib\site-packages\celery\app\control.py", line 776, in broadcast
    return self.mailbox(conn)._broadcast(
           ^^^^^^^^^^^^^^^^^^^^^^^^^^^^^^
  File "C:\Users\DELL\Desktop\portofolio_project\venv\Lib\site-packages\kombu\pidbox.py", line 330, in _broadcast
    chan = channel or self.connection.default_channel
                      ^^^^^^^^^^^^^^^^^^^^^^^^^^^^^^^
  File "C:\Users\DELL\Desktop\portofolio_project\venv\Lib\site-packages\kombu\connection.py", line 953, in default_channel
    self._ensure_connection(**conn_opts)
  File "C:\Users\DELL\Desktop\portofolio_project\venv\Lib\site-packages\kombu\connection.py", line 458, in _ensure_connection
    with ctx():
  File "C:\Users\DELL\AppData\Local\Programs\Python\Python312\Lib\contextlib.py", line 158, in __exit__
    self.gen.throw(value)
  File "C:\Users\DELL\Desktop\portofolio_project\venv\Lib\site-packages\kombu\connection.py", line 476, in _reraise_as_library_errors
    raise ConnectionError(str(exc)) from exc
kombu.exceptions.OperationalError: Connection closed by server.
2024-02-01 15:42:51,859 (ERROR) - asyncio - Future exception was never retrieved
future: <Future finished exception=OperationalError('Connection closed by server.')>
Traceback (most recent call last):
  File "C:\Users\DELL\Desktop\portofolio_project\venv\Lib\site-packages\kombu\transport\virtual\base.py", line 951, in create_channel
    return self._avail_channels.pop()
           ^^^^^^^^^^^^^^^^^^^^^^^^^^
IndexError: pop from empty list

During handling of the above exception, another exception occurred:

Traceback (most recent call last):
  File "C:\Users\DELL\Desktop\portofolio_project\venv\Lib\site-packages\kombu\connection.py", line 472, in _reraise_as_library_errors
    yield
  File "C:\Users\DELL\Desktop\portofolio_project\venv\Lib\site-packages\kombu\connection.py", line 459, in _ensure_connection
    return retry_over_time(
           ^^^^^^^^^^^^^^^^
  File "C:\Users\DELL\Desktop\portofolio_project\venv\Lib\site-packages\kombu\utils\functional.py", line 318, in retry_over_time
    return fun(*args, **kwargs)
           ^^^^^^^^^^^^^^^^^^^^
  File "C:\Users\DELL\Desktop\portofolio_project\venv\Lib\site-packages\kombu\connection.py", line 934, in _connection_factory
    self._connection = self._establish_connection()
                       ^^^^^^^^^^^^^^^^^^^^^^^^^^^^
  File "C:\Users\DELL\Desktop\portofolio_project\venv\Lib\site-packages\kombu\connection.py", line 860, in _establish_connection
    conn = self.transport.establish_connection()
           ^^^^^^^^^^^^^^^^^^^^^^^^^^^^^^^^^^^^^
  File "C:\Users\DELL\Desktop\portofolio_project\venv\Lib\site-packages\kombu\transport\virtual\base.py", line 975, in establish_connection
    self._avail_channels.append(self.create_channel(self))
                                ^^^^^^^^^^^^^^^^^^^^^^^^^
  File "C:\Users\DELL\Desktop\portofolio_project\venv\Lib\site-packages\kombu\transport\virtual\base.py", line 953, in create_channel
    channel = self.Channel(connection)
              ^^^^^^^^^^^^^^^^^^^^^^^^
  File "C:\Users\DELL\Desktop\portofolio_project\venv\Lib\site-packages\kombu\transport\redis.py", line 743, in __init__
    self.client.ping()
  File "C:\Users\DELL\Desktop\portofolio_project\venv\Lib\site-packages\redis\commands\core.py", line 1216, in ping
    return self.execute_command("PING", **kwargs)
           ^^^^^^^^^^^^^^^^^^^^^^^^^^^^^^^^^^^^^^
  File "C:\Users\DELL\Desktop\portofolio_project\venv\Lib\site-packages\redis\client.py", line 533, in execute_command
    conn = self.connection or pool.get_connection(command_name, **options)
                              ^^^^^^^^^^^^^^^^^^^^^^^^^^^^^^^^^^^^^^^^^^^^
  File "C:\Users\DELL\Desktop\portofolio_project\venv\Lib\site-packages\redis\connection.py", line 1086, in get_connection
    connection.connect()
  File "C:\Users\DELL\Desktop\portofolio_project\venv\Lib\site-packages\redis\connection.py", line 276, in connect
    self.on_connect()
  File "C:\Users\DELL\Desktop\portofolio_project\venv\Lib\site-packages\redis\connection.py", line 378, in on_connect
    self.send_command("CLIENT", "SETINFO", "LIB-NAME", self.lib_name)
  File "C:\Users\DELL\Desktop\portofolio_project\venv\Lib\site-packages\redis\connection.py", line 464, in send_command
    self.send_packed_command(
  File "C:\Users\DELL\Desktop\portofolio_project\venv\Lib\site-packages\redis\connection.py", line 437, in send_packed_command
    self.check_health()
  File "C:\Users\DELL\Desktop\portofolio_project\venv\Lib\site-packages\redis\connection.py", line 429, in check_health
    self.retry.call_with_retry(self._send_ping, self._ping_failed)
  File "C:\Users\DELL\Desktop\portofolio_project\venv\Lib\site-packages\redis\retry.py", line 51, in call_with_retry
    raise error
  File "C:\Users\DELL\Desktop\portofolio_project\venv\Lib\site-packages\redis\retry.py", line 46, in call_with_retry
    return do()
           ^^^^
  File "C:\Users\DELL\Desktop\portofolio_project\venv\Lib\site-packages\redis\connection.py", line 419, in _send_ping
    if str_if_bytes(self.read_response()) != "PONG":
                    ^^^^^^^^^^^^^^^^^^^^
  File "C:\Users\DELL\Desktop\portofolio_project\venv\Lib\site-packages\redis\connection.py", line 500, in read_response
    response = self._parser.read_response(disable_decoding=disable_decoding)
               ^^^^^^^^^^^^^^^^^^^^^^^^^^^^^^^^^^^^^^^^^^^^^^^^^^^^^^^^^^^^^
  File "C:\Users\DELL\Desktop\portofolio_project\venv\Lib\site-packages\redis\_parsers\resp2.py", line 15, in read_response
    result = self._read_response(disable_decoding=disable_decoding)
             ^^^^^^^^^^^^^^^^^^^^^^^^^^^^^^^^^^^^^^^^^^^^^^^^^^^^^^
  File "C:\Users\DELL\Desktop\portofolio_project\venv\Lib\site-packages\redis\_parsers\resp2.py", line 25, in _read_response
    raw = self._buffer.readline()
          ^^^^^^^^^^^^^^^^^^^^^^^
  File "C:\Users\DELL\Desktop\portofolio_project\venv\Lib\site-packages\redis\_parsers\socket.py", line 115, in readline
    self._read_from_socket()
  File "C:\Users\DELL\Desktop\portofolio_project\venv\Lib\site-packages\redis\_parsers\socket.py", line 68, in _read_from_socket
    raise ConnectionError(SERVER_CLOSED_CONNECTION_ERROR)
redis.exceptions.ConnectionError: Connection closed by server.

The above exception was the direct cause of the following exception:

Traceback (most recent call last):
  File "C:\Users\DELL\AppData\Local\Programs\Python\Python312\Lib\concurrent\futures\thread.py", line 58, in run
    result = self.fn(*self.args, **self.kwargs)
             ^^^^^^^^^^^^^^^^^^^^^^^^^^^^^^^^^^
  File "C:\Users\DELL\Desktop\portofolio_project\venv\Lib\site-packages\flower\inspector.py", line 37, in _inspect
    getattr(inspect, method)()
  File "C:\Users\DELL\Desktop\portofolio_project\venv\Lib\site-packages\celery\app\control.py", line 271, in registered
    return self._request('registered', taskinfoitems=taskinfoitems)
           ^^^^^^^^^^^^^^^^^^^^^^^^^^^^^^^^^^^^^^^^^^^^^^^^^^^^^^^^
  File "C:\Users\DELL\Desktop\portofolio_project\venv\Lib\site-packages\celery\app\control.py", line 106, in _request
    return self._prepare(self.app.control.broadcast(
                         ^^^^^^^^^^^^^^^^^^^^^^^^^^^
  File "C:\Users\DELL\Desktop\portofolio_project\venv\Lib\site-packages\celery\app\control.py", line 776, in broadcast
    return self.mailbox(conn)._broadcast(
           ^^^^^^^^^^^^^^^^^^^^^^^^^^^^^^
  File "C:\Users\DELL\Desktop\portofolio_project\venv\Lib\site-packages\kombu\pidbox.py", line 330, in _broadcast
    chan = channel or self.connection.default_channel
                      ^^^^^^^^^^^^^^^^^^^^^^^^^^^^^^^
  File "C:\Users\DELL\Desktop\portofolio_project\venv\Lib\site-packages\kombu\connection.py", line 953, in default_channel
    self._ensure_connection(**conn_opts)
  File "C:\Users\DELL\Desktop\portofolio_project\venv\Lib\site-packages\kombu\connection.py", line 458, in _ensure_connection
    with ctx():
  File "C:\Users\DELL\AppData\Local\Programs\Python\Python312\Lib\contextlib.py", line 158, in __exit__
    self.gen.throw(value)
  File "C:\Users\DELL\Desktop\portofolio_project\venv\Lib\site-packages\kombu\connection.py", line 476, in _reraise_as_library_errors
    raise ConnectionError(str(exc)) from exc
kombu.exceptions.OperationalError: Connection closed by server.
2024-02-01 15:42:51,878 (ERROR) - asyncio - Future exception was never retrieved
future: <Future finished exception=OperationalError('Connection closed by server.')>
Traceback (most recent call last):
  File "C:\Users\DELL\Desktop\portofolio_project\venv\Lib\site-packages\kombu\transport\virtual\base.py", line 951, in create_channel
    return self._avail_channels.pop()
           ^^^^^^^^^^^^^^^^^^^^^^^^^^
IndexError: pop from empty list

During handling of the above exception, another exception occurred:

Traceback (most recent call last):
  File "C:\Users\DELL\Desktop\portofolio_project\venv\Lib\site-packages\kombu\connection.py", line 472, in _reraise_as_library_errors
    yield
  File "C:\Users\DELL\Desktop\portofolio_project\venv\Lib\site-packages\kombu\connection.py", line 459, in _ensure_connection
    return retry_over_time(
           ^^^^^^^^^^^^^^^^
  File "C:\Users\DELL\Desktop\portofolio_project\venv\Lib\site-packages\kombu\utils\functional.py", line 318, in retry_over_time
    return fun(*args, **kwargs)
           ^^^^^^^^^^^^^^^^^^^^
  File "C:\Users\DELL\Desktop\portofolio_project\venv\Lib\site-packages\kombu\connection.py", line 934, in _connection_factory
    self._connection = self._establish_connection()
                       ^^^^^^^^^^^^^^^^^^^^^^^^^^^^
  File "C:\Users\DELL\Desktop\portofolio_project\venv\Lib\site-packages\kombu\connection.py", line 860, in _establish_connection
    conn = self.transport.establish_connection()
           ^^^^^^^^^^^^^^^^^^^^^^^^^^^^^^^^^^^^^
  File "C:\Users\DELL\Desktop\portofolio_project\venv\Lib\site-packages\kombu\transport\virtual\base.py", line 975, in establish_connection
    self._avail_channels.append(self.create_channel(self))
                                ^^^^^^^^^^^^^^^^^^^^^^^^^
  File "C:\Users\DELL\Desktop\portofolio_project\venv\Lib\site-packages\kombu\transport\virtual\base.py", line 953, in create_channel
    channel = self.Channel(connection)
              ^^^^^^^^^^^^^^^^^^^^^^^^
  File "C:\Users\DELL\Desktop\portofolio_project\venv\Lib\site-packages\kombu\transport\redis.py", line 743, in __init__
    self.client.ping()
  File "C:\Users\DELL\Desktop\portofolio_project\venv\Lib\site-packages\redis\commands\core.py", line 1216, in ping
    return self.execute_command("PING", **kwargs)
           ^^^^^^^^^^^^^^^^^^^^^^^^^^^^^^^^^^^^^^
  File "C:\Users\DELL\Desktop\portofolio_project\venv\Lib\site-packages\redis\client.py", line 533, in execute_command
    conn = self.connection or pool.get_connection(command_name, **options)
                              ^^^^^^^^^^^^^^^^^^^^^^^^^^^^^^^^^^^^^^^^^^^^
  File "C:\Users\DELL\Desktop\portofolio_project\venv\Lib\site-packages\redis\connection.py", line 1086, in get_connection
    connection.connect()
  File "C:\Users\DELL\Desktop\portofolio_project\venv\Lib\site-packages\redis\connection.py", line 276, in connect
    self.on_connect()
  File "C:\Users\DELL\Desktop\portofolio_project\venv\Lib\site-packages\redis\connection.py", line 378, in on_connect
    self.send_command("CLIENT", "SETINFO", "LIB-NAME", self.lib_name)
  File "C:\Users\DELL\Desktop\portofolio_project\venv\Lib\site-packages\redis\connection.py", line 464, in send_command
    self.send_packed_command(
  File "C:\Users\DELL\Desktop\portofolio_project\venv\Lib\site-packages\redis\connection.py", line 437, in send_packed_command
    self.check_health()
  File "C:\Users\DELL\Desktop\portofolio_project\venv\Lib\site-packages\redis\connection.py", line 429, in check_health
    self.retry.call_with_retry(self._send_ping, self._ping_failed)
  File "C:\Users\DELL\Desktop\portofolio_project\venv\Lib\site-packages\redis\retry.py", line 51, in call_with_retry
    raise error
  File "C:\Users\DELL\Desktop\portofolio_project\venv\Lib\site-packages\redis\retry.py", line 46, in call_with_retry
    return do()
           ^^^^
  File "C:\Users\DELL\Desktop\portofolio_project\venv\Lib\site-packages\redis\connection.py", line 419, in _send_ping
    if str_if_bytes(self.read_response()) != "PONG":
                    ^^^^^^^^^^^^^^^^^^^^
  File "C:\Users\DELL\Desktop\portofolio_project\venv\Lib\site-packages\redis\connection.py", line 500, in read_response
    response = self._parser.read_response(disable_decoding=disable_decoding)
               ^^^^^^^^^^^^^^^^^^^^^^^^^^^^^^^^^^^^^^^^^^^^^^^^^^^^^^^^^^^^^
  File "C:\Users\DELL\Desktop\portofolio_project\venv\Lib\site-packages\redis\_parsers\resp2.py", line 15, in read_response
    result = self._read_response(disable_decoding=disable_decoding)
             ^^^^^^^^^^^^^^^^^^^^^^^^^^^^^^^^^^^^^^^^^^^^^^^^^^^^^^
  File "C:\Users\DELL\Desktop\portofolio_project\venv\Lib\site-packages\redis\_parsers\resp2.py", line 25, in _read_response
    raw = self._buffer.readline()
          ^^^^^^^^^^^^^^^^^^^^^^^
  File "C:\Users\DELL\Desktop\portofolio_project\venv\Lib\site-packages\redis\_parsers\socket.py", line 115, in readline
    self._read_from_socket()
  File "C:\Users\DELL\Desktop\portofolio_project\venv\Lib\site-packages\redis\_parsers\socket.py", line 68, in _read_from_socket
    raise ConnectionError(SERVER_CLOSED_CONNECTION_ERROR)
redis.exceptions.ConnectionError: Connection closed by server.

The above exception was the direct cause of the following exception:

Traceback (most recent call last):
  File "C:\Users\DELL\AppData\Local\Programs\Python\Python312\Lib\concurrent\futures\thread.py", line 58, in run
    result = self.fn(*self.args, **self.kwargs)
             ^^^^^^^^^^^^^^^^^^^^^^^^^^^^^^^^^^
  File "C:\Users\DELL\Desktop\portofolio_project\venv\Lib\site-packages\flower\inspector.py", line 37, in _inspect
    getattr(inspect, method)()
  File "C:\Users\DELL\Desktop\portofolio_project\venv\Lib\site-packages\celery\app\control.py", line 254, in revoked
    return self._request('revoked')
           ^^^^^^^^^^^^^^^^^^^^^^^^
  File "C:\Users\DELL\Desktop\portofolio_project\venv\Lib\site-packages\celery\app\control.py", line 106, in _request
    return self._prepare(self.app.control.broadcast(
                         ^^^^^^^^^^^^^^^^^^^^^^^^^^^
  File "C:\Users\DELL\Desktop\portofolio_project\venv\Lib\site-packages\celery\app\control.py", line 776, in broadcast
    return self.mailbox(conn)._broadcast(
           ^^^^^^^^^^^^^^^^^^^^^^^^^^^^^^
  File "C:\Users\DELL\Desktop\portofolio_project\venv\Lib\site-packages\kombu\pidbox.py", line 330, in _broadcast
    chan = channel or self.connection.default_channel
                      ^^^^^^^^^^^^^^^^^^^^^^^^^^^^^^^
  File "C:\Users\DELL\Desktop\portofolio_project\venv\Lib\site-packages\kombu\connection.py", line 953, in default_channel
    self._ensure_connection(**conn_opts)
  File "C:\Users\DELL\Desktop\portofolio_project\venv\Lib\site-packages\kombu\connection.py", line 458, in _ensure_connection
    with ctx():
  File "C:\Users\DELL\AppData\Local\Programs\Python\Python312\Lib\contextlib.py", line 158, in __exit__
    self.gen.throw(value)
  File "C:\Users\DELL\Desktop\portofolio_project\venv\Lib\site-packages\kombu\connection.py", line 476, in _reraise_as_library_errors
    raise ConnectionError(str(exc)) from exc
kombu.exceptions.OperationalError: Connection closed by server.
2024-02-01 15:42:51,897 (ERROR) - asyncio - Future exception was never retrieved
future: <Future finished exception=OperationalError('Connection closed by server.')>
Traceback (most recent call last):
  File "C:\Users\DELL\Desktop\portofolio_project\venv\Lib\site-packages\kombu\transport\virtual\base.py", line 951, in create_channel
    return self._avail_channels.pop()
           ^^^^^^^^^^^^^^^^^^^^^^^^^^
IndexError: pop from empty list

During handling of the above exception, another exception occurred:

Traceback (most recent call last):
  File "C:\Users\DELL\Desktop\portofolio_project\venv\Lib\site-packages\kombu\connection.py", line 472, in _reraise_as_library_errors
    yield
  File "C:\Users\DELL\Desktop\portofolio_project\venv\Lib\site-packages\kombu\connection.py", line 459, in _ensure_connection
    return retry_over_time(
           ^^^^^^^^^^^^^^^^
  File "C:\Users\DELL\Desktop\portofolio_project\venv\Lib\site-packages\kombu\utils\functional.py", line 318, in retry_over_time
    return fun(*args, **kwargs)
           ^^^^^^^^^^^^^^^^^^^^
  File "C:\Users\DELL\Desktop\portofolio_project\venv\Lib\site-packages\kombu\connection.py", line 934, in _connection_factory
    self._connection = self._establish_connection()
                       ^^^^^^^^^^^^^^^^^^^^^^^^^^^^
  File "C:\Users\DELL\Desktop\portofolio_project\venv\Lib\site-packages\kombu\connection.py", line 860, in _establish_connection
    conn = self.transport.establish_connection()
           ^^^^^^^^^^^^^^^^^^^^^^^^^^^^^^^^^^^^^
  File "C:\Users\DELL\Desktop\portofolio_project\venv\Lib\site-packages\kombu\transport\virtual\base.py", line 975, in establish_connection
    self._avail_channels.append(self.create_channel(self))
                                ^^^^^^^^^^^^^^^^^^^^^^^^^
  File "C:\Users\DELL\Desktop\portofolio_project\venv\Lib\site-packages\kombu\transport\virtual\base.py", line 953, in create_channel
    channel = self.Channel(connection)
              ^^^^^^^^^^^^^^^^^^^^^^^^
  File "C:\Users\DELL\Desktop\portofolio_project\venv\Lib\site-packages\kombu\transport\redis.py", line 743, in __init__
    self.client.ping()
  File "C:\Users\DELL\Desktop\portofolio_project\venv\Lib\site-packages\redis\commands\core.py", line 1216, in ping
    return self.execute_command("PING", **kwargs)
           ^^^^^^^^^^^^^^^^^^^^^^^^^^^^^^^^^^^^^^
  File "C:\Users\DELL\Desktop\portofolio_project\venv\Lib\site-packages\redis\client.py", line 533, in execute_command
    conn = self.connection or pool.get_connection(command_name, **options)
                              ^^^^^^^^^^^^^^^^^^^^^^^^^^^^^^^^^^^^^^^^^^^^
  File "C:\Users\DELL\Desktop\portofolio_project\venv\Lib\site-packages\redis\connection.py", line 1086, in get_connection
    connection.connect()
  File "C:\Users\DELL\Desktop\portofolio_project\venv\Lib\site-packages\redis\connection.py", line 276, in connect
    self.on_connect()
  File "C:\Users\DELL\Desktop\portofolio_project\venv\Lib\site-packages\redis\connection.py", line 378, in on_connect
    self.send_command("CLIENT", "SETINFO", "LIB-NAME", self.lib_name)
  File "C:\Users\DELL\Desktop\portofolio_project\venv\Lib\site-packages\redis\connection.py", line 464, in send_command
    self.send_packed_command(
  File "C:\Users\DELL\Desktop\portofolio_project\venv\Lib\site-packages\redis\connection.py", line 437, in send_packed_command
    self.check_health()
  File "C:\Users\DELL\Desktop\portofolio_project\venv\Lib\site-packages\redis\connection.py", line 429, in check_health
    self.retry.call_with_retry(self._send_ping, self._ping_failed)
  File "C:\Users\DELL\Desktop\portofolio_project\venv\Lib\site-packages\redis\retry.py", line 51, in call_with_retry
    raise error
  File "C:\Users\DELL\Desktop\portofolio_project\venv\Lib\site-packages\redis\retry.py", line 46, in call_with_retry
    return do()
           ^^^^
  File "C:\Users\DELL\Desktop\portofolio_project\venv\Lib\site-packages\redis\connection.py", line 419, in _send_ping
    if str_if_bytes(self.read_response()) != "PONG":
                    ^^^^^^^^^^^^^^^^^^^^
  File "C:\Users\DELL\Desktop\portofolio_project\venv\Lib\site-packages\redis\connection.py", line 500, in read_response
    response = self._parser.read_response(disable_decoding=disable_decoding)
               ^^^^^^^^^^^^^^^^^^^^^^^^^^^^^^^^^^^^^^^^^^^^^^^^^^^^^^^^^^^^^
  File "C:\Users\DELL\Desktop\portofolio_project\venv\Lib\site-packages\redis\_parsers\resp2.py", line 15, in read_response
    result = self._read_response(disable_decoding=disable_decoding)
             ^^^^^^^^^^^^^^^^^^^^^^^^^^^^^^^^^^^^^^^^^^^^^^^^^^^^^^
  File "C:\Users\DELL\Desktop\portofolio_project\venv\Lib\site-packages\redis\_parsers\resp2.py", line 25, in _read_response
    raw = self._buffer.readline()
          ^^^^^^^^^^^^^^^^^^^^^^^
  File "C:\Users\DELL\Desktop\portofolio_project\venv\Lib\site-packages\redis\_parsers\socket.py", line 115, in readline
    self._read_from_socket()
  File "C:\Users\DELL\Desktop\portofolio_project\venv\Lib\site-packages\redis\_parsers\socket.py", line 68, in _read_from_socket
    raise ConnectionError(SERVER_CLOSED_CONNECTION_ERROR)
redis.exceptions.ConnectionError: Connection closed by server.

The above exception was the direct cause of the following exception:

Traceback (most recent call last):
  File "C:\Users\DELL\AppData\Local\Programs\Python\Python312\Lib\concurrent\futures\thread.py", line 58, in run
    result = self.fn(*self.args, **self.kwargs)
             ^^^^^^^^^^^^^^^^^^^^^^^^^^^^^^^^^^
  File "C:\Users\DELL\Desktop\portofolio_project\venv\Lib\site-packages\flower\inspector.py", line 37, in _inspect
    getattr(inspect, method)()
  File "C:\Users\DELL\Desktop\portofolio_project\venv\Lib\site-packages\celery\app\control.py", line 177, in reserved
    return self._request('reserved')
           ^^^^^^^^^^^^^^^^^^^^^^^^^
  File "C:\Users\DELL\Desktop\portofolio_project\venv\Lib\site-packages\celery\app\control.py", line 106, in _request
    return self._prepare(self.app.control.broadcast(
                         ^^^^^^^^^^^^^^^^^^^^^^^^^^^
  File "C:\Users\DELL\Desktop\portofolio_project\venv\Lib\site-packages\celery\app\control.py", line 776, in broadcast
    return self.mailbox(conn)._broadcast(
           ^^^^^^^^^^^^^^^^^^^^^^^^^^^^^^
  File "C:\Users\DELL\Desktop\portofolio_project\venv\Lib\site-packages\kombu\pidbox.py", line 330, in _broadcast
    chan = channel or self.connection.default_channel
                      ^^^^^^^^^^^^^^^^^^^^^^^^^^^^^^^
  File "C:\Users\DELL\Desktop\portofolio_project\venv\Lib\site-packages\kombu\connection.py", line 953, in default_channel
    self._ensure_connection(**conn_opts)
  File "C:\Users\DELL\Desktop\portofolio_project\venv\Lib\site-packages\kombu\connection.py", line 458, in _ensure_connection
    with ctx():
  File "C:\Users\DELL\AppData\Local\Programs\Python\Python312\Lib\contextlib.py", line 158, in __exit__
    self.gen.throw(value)
  File "C:\Users\DELL\Desktop\portofolio_project\venv\Lib\site-packages\kombu\connection.py", line 476, in _reraise_as_library_errors
    raise ConnectionError(str(exc)) from exc
kombu.exceptions.OperationalError: Connection closed by server.
2024-02-01 15:42:51,912 (ERROR) - asyncio - Future exception was never retrieved
future: <Future finished exception=OperationalError('Connection closed by server.')>
Traceback (most recent call last):
  File "C:\Users\DELL\Desktop\portofolio_project\venv\Lib\site-packages\kombu\transport\virtual\base.py", line 951, in create_channel
    return self._avail_channels.pop()
           ^^^^^^^^^^^^^^^^^^^^^^^^^^
IndexError: pop from empty list

During handling of the above exception, another exception occurred:

Traceback (most recent call last):
  File "C:\Users\DELL\Desktop\portofolio_project\venv\Lib\site-packages\kombu\connection.py", line 472, in _reraise_as_library_errors
    yield
  File "C:\Users\DELL\Desktop\portofolio_project\venv\Lib\site-packages\kombu\connection.py", line 459, in _ensure_connection
    return retry_over_time(
           ^^^^^^^^^^^^^^^^
  File "C:\Users\DELL\Desktop\portofolio_project\venv\Lib\site-packages\kombu\utils\functional.py", line 318, in retry_over_time
    return fun(*args, **kwargs)
           ^^^^^^^^^^^^^^^^^^^^
  File "C:\Users\DELL\Desktop\portofolio_project\venv\Lib\site-packages\kombu\connection.py", line 934, in _connection_factory
    self._connection = self._establish_connection()
                       ^^^^^^^^^^^^^^^^^^^^^^^^^^^^
  File "C:\Users\DELL\Desktop\portofolio_project\venv\Lib\site-packages\kombu\connection.py", line 860, in _establish_connection
    conn = self.transport.establish_connection()
           ^^^^^^^^^^^^^^^^^^^^^^^^^^^^^^^^^^^^^
  File "C:\Users\DELL\Desktop\portofolio_project\venv\Lib\site-packages\kombu\transport\virtual\base.py", line 975, in establish_connection
    self._avail_channels.append(self.create_channel(self))
                                ^^^^^^^^^^^^^^^^^^^^^^^^^
  File "C:\Users\DELL\Desktop\portofolio_project\venv\Lib\site-packages\kombu\transport\virtual\base.py", line 953, in create_channel
    channel = self.Channel(connection)
              ^^^^^^^^^^^^^^^^^^^^^^^^
  File "C:\Users\DELL\Desktop\portofolio_project\venv\Lib\site-packages\kombu\transport\redis.py", line 743, in __init__
    self.client.ping()
  File "C:\Users\DELL\Desktop\portofolio_project\venv\Lib\site-packages\redis\commands\core.py", line 1216, in ping
    return self.execute_command("PING", **kwargs)
           ^^^^^^^^^^^^^^^^^^^^^^^^^^^^^^^^^^^^^^
  File "C:\Users\DELL\Desktop\portofolio_project\venv\Lib\site-packages\redis\client.py", line 533, in execute_command
    conn = self.connection or pool.get_connection(command_name, **options)
                              ^^^^^^^^^^^^^^^^^^^^^^^^^^^^^^^^^^^^^^^^^^^^
  File "C:\Users\DELL\Desktop\portofolio_project\venv\Lib\site-packages\redis\connection.py", line 1086, in get_connection
    connection.connect()
  File "C:\Users\DELL\Desktop\portofolio_project\venv\Lib\site-packages\redis\connection.py", line 276, in connect
    self.on_connect()
  File "C:\Users\DELL\Desktop\portofolio_project\venv\Lib\site-packages\redis\connection.py", line 378, in on_connect
    self.send_command("CLIENT", "SETINFO", "LIB-NAME", self.lib_name)
  File "C:\Users\DELL\Desktop\portofolio_project\venv\Lib\site-packages\redis\connection.py", line 464, in send_command
    self.send_packed_command(
  File "C:\Users\DELL\Desktop\portofolio_project\venv\Lib\site-packages\redis\connection.py", line 437, in send_packed_command
    self.check_health()
  File "C:\Users\DELL\Desktop\portofolio_project\venv\Lib\site-packages\redis\connection.py", line 429, in check_health
    self.retry.call_with_retry(self._send_ping, self._ping_failed)
  File "C:\Users\DELL\Desktop\portofolio_project\venv\Lib\site-packages\redis\retry.py", line 51, in call_with_retry
    raise error
  File "C:\Users\DELL\Desktop\portofolio_project\venv\Lib\site-packages\redis\retry.py", line 46, in call_with_retry
    return do()
           ^^^^
  File "C:\Users\DELL\Desktop\portofolio_project\venv\Lib\site-packages\redis\connection.py", line 419, in _send_ping
    if str_if_bytes(self.read_response()) != "PONG":
                    ^^^^^^^^^^^^^^^^^^^^
  File "C:\Users\DELL\Desktop\portofolio_project\venv\Lib\site-packages\redis\connection.py", line 500, in read_response
    response = self._parser.read_response(disable_decoding=disable_decoding)
               ^^^^^^^^^^^^^^^^^^^^^^^^^^^^^^^^^^^^^^^^^^^^^^^^^^^^^^^^^^^^^
  File "C:\Users\DELL\Desktop\portofolio_project\venv\Lib\site-packages\redis\_parsers\resp2.py", line 15, in read_response
    result = self._read_response(disable_decoding=disable_decoding)
             ^^^^^^^^^^^^^^^^^^^^^^^^^^^^^^^^^^^^^^^^^^^^^^^^^^^^^^
  File "C:\Users\DELL\Desktop\portofolio_project\venv\Lib\site-packages\redis\_parsers\resp2.py", line 25, in _read_response
    raw = self._buffer.readline()
          ^^^^^^^^^^^^^^^^^^^^^^^
  File "C:\Users\DELL\Desktop\portofolio_project\venv\Lib\site-packages\redis\_parsers\socket.py", line 115, in readline
    self._read_from_socket()
  File "C:\Users\DELL\Desktop\portofolio_project\venv\Lib\site-packages\redis\_parsers\socket.py", line 68, in _read_from_socket
    raise ConnectionError(SERVER_CLOSED_CONNECTION_ERROR)
redis.exceptions.ConnectionError: Connection closed by server.

The above exception was the direct cause of the following exception:

Traceback (most recent call last):
  File "C:\Users\DELL\AppData\Local\Programs\Python\Python312\Lib\concurrent\futures\thread.py", line 58, in run
    result = self.fn(*self.args, **self.kwargs)
             ^^^^^^^^^^^^^^^^^^^^^^^^^^^^^^^^^^
  File "C:\Users\DELL\Desktop\portofolio_project\venv\Lib\site-packages\flower\inspector.py", line 37, in _inspect
    getattr(inspect, method)()
  File "C:\Users\DELL\Desktop\portofolio_project\venv\Lib\site-packages\celery\app\control.py", line 243, in stats
    return self._request('stats')
           ^^^^^^^^^^^^^^^^^^^^^^
  File "C:\Users\DELL\Desktop\portofolio_project\venv\Lib\site-packages\celery\app\control.py", line 106, in _request
    return self._prepare(self.app.control.broadcast(
                         ^^^^^^^^^^^^^^^^^^^^^^^^^^^
  File "C:\Users\DELL\Desktop\portofolio_project\venv\Lib\site-packages\celery\app\control.py", line 776, in broadcast
    return self.mailbox(conn)._broadcast(
           ^^^^^^^^^^^^^^^^^^^^^^^^^^^^^^
  File "C:\Users\DELL\Desktop\portofolio_project\venv\Lib\site-packages\kombu\pidbox.py", line 330, in _broadcast
    chan = channel or self.connection.default_channel
                      ^^^^^^^^^^^^^^^^^^^^^^^^^^^^^^^
  File "C:\Users\DELL\Desktop\portofolio_project\venv\Lib\site-packages\kombu\connection.py", line 953, in default_channel
    self._ensure_connection(**conn_opts)
  File "C:\Users\DELL\Desktop\portofolio_project\venv\Lib\site-packages\kombu\connection.py", line 458, in _ensure_connection
    with ctx():
  File "C:\Users\DELL\AppData\Local\Programs\Python\Python312\Lib\contextlib.py", line 158, in __exit__
    self.gen.throw(value)
  File "C:\Users\DELL\Desktop\portofolio_project\venv\Lib\site-packages\kombu\connection.py", line 476, in _reraise_as_library_errors
    raise ConnectionError(str(exc)) from exc
kombu.exceptions.OperationalError: Connection closed by server.
2024-02-01 15:42:51,937 (ERROR) - asyncio - Future exception was never retrieved
future: <Future finished exception=OperationalError('Connection closed by server.')>
Traceback (most recent call last):
  File "C:\Users\DELL\Desktop\portofolio_project\venv\Lib\site-packages\kombu\transport\virtual\base.py", line 951, in create_channel
    return self._avail_channels.pop()
           ^^^^^^^^^^^^^^^^^^^^^^^^^^
IndexError: pop from empty list

During handling of the above exception, another exception occurred:

Traceback (most recent call last):
  File "C:\Users\DELL\Desktop\portofolio_project\venv\Lib\site-packages\kombu\connection.py", line 472, in _reraise_as_library_errors
    yield
  File "C:\Users\DELL\Desktop\portofolio_project\venv\Lib\site-packages\kombu\connection.py", line 459, in _ensure_connection
    return retry_over_time(
           ^^^^^^^^^^^^^^^^
  File "C:\Users\DELL\Desktop\portofolio_project\venv\Lib\site-packages\kombu\utils\functional.py", line 318, in retry_over_time
    return fun(*args, **kwargs)
           ^^^^^^^^^^^^^^^^^^^^
  File "C:\Users\DELL\Desktop\portofolio_project\venv\Lib\site-packages\kombu\connection.py", line 934, in _connection_factory
    self._connection = self._establish_connection()
                       ^^^^^^^^^^^^^^^^^^^^^^^^^^^^
  File "C:\Users\DELL\Desktop\portofolio_project\venv\Lib\site-packages\kombu\connection.py", line 860, in _establish_connection
    conn = self.transport.establish_connection()
           ^^^^^^^^^^^^^^^^^^^^^^^^^^^^^^^^^^^^^
  File "C:\Users\DELL\Desktop\portofolio_project\venv\Lib\site-packages\kombu\transport\virtual\base.py", line 975, in establish_connection
    self._avail_channels.append(self.create_channel(self))
                                ^^^^^^^^^^^^^^^^^^^^^^^^^
  File "C:\Users\DELL\Desktop\portofolio_project\venv\Lib\site-packages\kombu\transport\virtual\base.py", line 953, in create_channel
    channel = self.Channel(connection)
              ^^^^^^^^^^^^^^^^^^^^^^^^
  File "C:\Users\DELL\Desktop\portofolio_project\venv\Lib\site-packages\kombu\transport\redis.py", line 743, in __init__
    self.client.ping()
  File "C:\Users\DELL\Desktop\portofolio_project\venv\Lib\site-packages\redis\commands\core.py", line 1216, in ping
    return self.execute_command("PING", **kwargs)
           ^^^^^^^^^^^^^^^^^^^^^^^^^^^^^^^^^^^^^^
  File "C:\Users\DELL\Desktop\portofolio_project\venv\Lib\site-packages\redis\client.py", line 533, in execute_command
    conn = self.connection or pool.get_connection(command_name, **options)
                              ^^^^^^^^^^^^^^^^^^^^^^^^^^^^^^^^^^^^^^^^^^^^
  File "C:\Users\DELL\Desktop\portofolio_project\venv\Lib\site-packages\redis\connection.py", line 1086, in get_connection
    connection.connect()
  File "C:\Users\DELL\Desktop\portofolio_project\venv\Lib\site-packages\redis\connection.py", line 276, in connect
    self.on_connect()
  File "C:\Users\DELL\Desktop\portofolio_project\venv\Lib\site-packages\redis\connection.py", line 378, in on_connect
    self.send_command("CLIENT", "SETINFO", "LIB-NAME", self.lib_name)
  File "C:\Users\DELL\Desktop\portofolio_project\venv\Lib\site-packages\redis\connection.py", line 464, in send_command
    self.send_packed_command(
  File "C:\Users\DELL\Desktop\portofolio_project\venv\Lib\site-packages\redis\connection.py", line 437, in send_packed_command
    self.check_health()
  File "C:\Users\DELL\Desktop\portofolio_project\venv\Lib\site-packages\redis\connection.py", line 429, in check_health
    self.retry.call_with_retry(self._send_ping, self._ping_failed)
  File "C:\Users\DELL\Desktop\portofolio_project\venv\Lib\site-packages\redis\retry.py", line 51, in call_with_retry
    raise error
  File "C:\Users\DELL\Desktop\portofolio_project\venv\Lib\site-packages\redis\retry.py", line 46, in call_with_retry
    return do()
           ^^^^
  File "C:\Users\DELL\Desktop\portofolio_project\venv\Lib\site-packages\redis\connection.py", line 419, in _send_ping
    if str_if_bytes(self.read_response()) != "PONG":
                    ^^^^^^^^^^^^^^^^^^^^
  File "C:\Users\DELL\Desktop\portofolio_project\venv\Lib\site-packages\redis\connection.py", line 500, in read_response
    response = self._parser.read_response(disable_decoding=disable_decoding)
               ^^^^^^^^^^^^^^^^^^^^^^^^^^^^^^^^^^^^^^^^^^^^^^^^^^^^^^^^^^^^^
  File "C:\Users\DELL\Desktop\portofolio_project\venv\Lib\site-packages\redis\_parsers\resp2.py", line 15, in read_response
    result = self._read_response(disable_decoding=disable_decoding)
             ^^^^^^^^^^^^^^^^^^^^^^^^^^^^^^^^^^^^^^^^^^^^^^^^^^^^^^
  File "C:\Users\DELL\Desktop\portofolio_project\venv\Lib\site-packages\redis\_parsers\resp2.py", line 25, in _read_response
    raw = self._buffer.readline()
          ^^^^^^^^^^^^^^^^^^^^^^^
  File "C:\Users\DELL\Desktop\portofolio_project\venv\Lib\site-packages\redis\_parsers\socket.py", line 115, in readline
    self._read_from_socket()
  File "C:\Users\DELL\Desktop\portofolio_project\venv\Lib\site-packages\redis\_parsers\socket.py", line 68, in _read_from_socket
    raise ConnectionError(SERVER_CLOSED_CONNECTION_ERROR)
redis.exceptions.ConnectionError: Connection closed by server.

The above exception was the direct cause of the following exception:

Traceback (most recent call last):
  File "C:\Users\DELL\AppData\Local\Programs\Python\Python312\Lib\concurrent\futures\thread.py", line 58, in run
    result = self.fn(*self.args, **self.kwargs)
             ^^^^^^^^^^^^^^^^^^^^^^^^^^^^^^^^^^
  File "C:\Users\DELL\Desktop\portofolio_project\venv\Lib\site-packages\flower\inspector.py", line 37, in _inspect
    getattr(inspect, method)()
  File "C:\Users\DELL\Desktop\portofolio_project\venv\Lib\site-packages\celery\app\control.py", line 166, in scheduled
    return self._request('scheduled')
           ^^^^^^^^^^^^^^^^^^^^^^^^^^
  File "C:\Users\DELL\Desktop\portofolio_project\venv\Lib\site-packages\celery\app\control.py", line 106, in _request
    return self._prepare(self.app.control.broadcast(
                         ^^^^^^^^^^^^^^^^^^^^^^^^^^^
  File "C:\Users\DELL\Desktop\portofolio_project\venv\Lib\site-packages\celery\app\control.py", line 776, in broadcast
    return self.mailbox(conn)._broadcast(
           ^^^^^^^^^^^^^^^^^^^^^^^^^^^^^^
  File "C:\Users\DELL\Desktop\portofolio_project\venv\Lib\site-packages\kombu\pidbox.py", line 330, in _broadcast
    chan = channel or self.connection.default_channel
                      ^^^^^^^^^^^^^^^^^^^^^^^^^^^^^^^
  File "C:\Users\DELL\Desktop\portofolio_project\venv\Lib\site-packages\kombu\connection.py", line 953, in default_channel
    self._ensure_connection(**conn_opts)
  File "C:\Users\DELL\Desktop\portofolio_project\venv\Lib\site-packages\kombu\connection.py", line 458, in _ensure_connection
    with ctx():
  File "C:\Users\DELL\AppData\Local\Programs\Python\Python312\Lib\contextlib.py", line 158, in __exit__
    self.gen.throw(value)
  File "C:\Users\DELL\Desktop\portofolio_project\venv\Lib\site-packages\kombu\connection.py", line 476, in _reraise_as_library_errors
    raise ConnectionError(str(exc)) from exc
kombu.exceptions.OperationalError: Connection closed by server.
2024-02-01 15:59:39,084 (INFO) - django.utils.autoreload - Watching for file changes with StatReloader
2024-02-01 16:07:56,266 (INFO) - django.utils.autoreload - Watching for file changes with StatReloader
